Workbook

Sheet CV Coop LLP Primary Alloc
A1: CV COOP PRIMARY SPECIES ALLOCATIONS by LLP | I1: 2204.62 | K1: Updated for 2026
D2: 2026 | E2: CV TAC (mt) | F2: CV QS POOL | G2: CV TAC (lbs)
D3: POP | E3: ='TAC Sector Allocations'!J6 -> 14806.072 | F3: ='Alloc by Sector'!D19 -> 60000262 | G3: =E3*$I$1 -> 32641763
D4: NR | E4: ='TAC Sector Allocations'!J9 -> 2022.4208 | F4: ='Alloc by Sector'!D20 -> 27754394 | G4: =E4*$I$1 -> 4458669.3 | I4: =G6*0.4 -> 17870481 | J4: 40% Processing Cap for Primary Rockfish
D5: Dusky | E5: ='TAC Sector Allocations'!J12 -> 3436.3151 | F5: ='Alloc by Sector'!D21 -> 19486501 | G5: =E5*$I$1 -> 7575768.9 | I5: =G3*0.08 -> 2611341.1 | J5: 8% POP only Harvest Cap
D6: TOTAL | E6: =SUM(E3:E5) -> 20264.808 | F6: =SUM(F3:F5) -> 107241157 | G6: =SUM(G3:G5) -> 44676202
A7: Silver Bay Seafoods
C8: QS UNITS | G8: 2026 TAC - METRIC TONS | K8: 2026 TAC - POUNDS | P8: % CV Pool Harvest Allocation for Exhibit B
A9: LLP | B9: Vessel | D9: POP | E9: DUSKY | F9: TOTAL | G9: POP | H9: NR | I9: DUSKY | J9: TOTAL | K9: POP | L9: NR | M9: DUSKY | N9: TOTAL | P9: POP | Q9: NR | R9: Dusky
A10: 2696 | B10: MAR PACIFICO | C10: 1973449 | D10: 1253570 | E10: 780343 | F10: =SUM(C10:E10) -> 4007362 | G10: =+C10/$F$3*$E$3 -> 486.98169 | H10: =+D10/$F$4*$E$4 -> 91.345754 | I10: =+E10/$F$5*$E$5 -> 137.60831 | J10: =SUM(G10:I10) -> 715.93575 | K10: =+G10*$I$1 -> 1073609.6 | L10: =+H10*$I$1 -> 201382.68 | M10: =+I10*$I$1 -> 303374.03 | N10: =SUM(K10:M10) -> 1578366.3 | P10: =C10/$F$3 -> 0.032890673 | Q10: =D10/$F$4 -> 0.045166542 | R10: =E10/$F$5 -> 0.040045311
A11: 1554 | B11: CHELLISSA | C11: 510284 | D11: 238904 | E11: 161211 | F11: =SUM(C11:E11) -> 910399 | G11: =+C11/$F$3*$E$3 -> 125.92115 | H11: =+D11/$F$4*$E$4 -> 17.408574 | I11: =+E11/$F$5*$E$5 -> 28.428489 | J11: =SUM(G11:I11) -> 171.75821 | K11: =+G11*$I$1 -> 277608.28 | L11: =+H11*$I$1 -> 38379.29 | M11: =+I11*$I$1 -> 62674.016 | N11: =SUM(K11:M11) -> 378661.59 | P11: =C11/$F$3 -> 0.0085046962 | Q11: =D11/$F$4 -> 0.0086077902 | R11: =E11/$F$5 -> 0.0082729578
A12: 2165 | B12: DAWN | C12: 1257125 | D12: 307669 | E12: 339446 | F12: =SUM(C12:E12) -> 1904240 | G12: =+C12/$F$3*$E$3 -> 310.21671 | H12: =+D12/$F$4*$E$4 -> 22.419376 | I12: =+E12/$F$5*$E$5 -> 59.859048 | J12: =SUM(G12:I12) -> 392.49513 | K12: =+G12*$I$1 -> 683909.96 | L12: =+H12*$I$1 -> 49426.204 | M12: =+I12*$I$1 -> 131966.46 | N12: =SUM(K12:M12) -> 865302.62 | P12: =C12/$F$3 -> 0.020951992 | Q12: =D12/$F$4 -> 0.011085416 | R12: =E12/$F$5 -> 0.017419546
A13: 1841 | B13: MAR DEL NORTE | C13: 1479627 | D13: 765284 | E13: 437036 | F13: =SUM(C13:E13) -> 2681947 | G13: =+C13/$F$3*$E$3 -> 365.12281 | H13: =+D13/$F$4*$E$4 -> 55.76509 | I13: =+E13/$F$5*$E$5 -> 77.068397 | J13: =SUM(G13:I13) -> 497.9563 | K13: =+G13*$I$1 -> 804957.06 | L13: =+H13*$I$1 -> 122940.83 | M13: =+I13*$I$1 -> 169906.53 | N13: =SUM(K13:M13) -> 1097804.4 | P13: =C13/$F$3 -> 0.024660342 | Q13: =D13/$F$4 -> 0.027573436 | R13: =E13/$F$5 -> 0.022427628
A14: 4851 | B14: PK FISH HOLDINGS | C14: 1100949 | D14: 608301 | E14: 260197 | F14: =SUM(C14:E14) -> 1969447 | G14: =+C14/$F$3*$E$3 -> 271.67766 | H14: =+D14/$F$4*$E$4 -> 44.325976 | I14: =+E14/$F$5*$E$5 -> 45.884013 | J14: =SUM(G14:I14) -> 361.88765 | K14: =+G14*$I$1 -> 598946 | L14: =+H14*$I$1 -> 97721.932 | M14: =+I14*$I$1 -> 101156.81 | N14: =SUM(K14:M14) -> 797824.74 | P14: =C14/$F$3 -> 0.01834907 | Q14: =D14/$F$4 -> 0.021917286 | R14: =E14/$F$5 -> 0.013352679
A15: 3665 | B15: EVIE GRACE | C15: 2506083 | D15: 1296343 | E15: 775881 | F15: =SUM(C15:E15) -> 4578307 | G15: =+C15/$F$3*$E$3 -> 618.41807 | H15: =+D15/$F$4*$E$4 -> 94.462557 | I15: =+E15/$F$5*$E$5 -> 136.82146 | J15: =SUM(G15:I15) -> 849.70209 | K15: =+G15*$I$1 -> 1363376.8 | L15: =+H15*$I$1 -> 208254.04 | M15: =+I15*$I$1 -> 301639.33 | N15: =SUM(K15:M15) -> 1873270.2 | P15: =C15/$F$3 -> 0.041767868 | Q15: =D15/$F$4 -> 0.046707667 | R15: =E15/$F$5 -> 0.039816332
A16: 3496 | B16: MiRoCo | C16: 972179 | D16: 956843 | E16: 663736 | F16: =SUM(C16:E16) -> 2592758 | G16: =+C16/$F$3*$E$3 -> 239.9015 | H16: =+D16/$F$4*$E$4 -> 69.723705 | I16: =+E16/$F$5*$E$5 -> 117.04544 | J16: =SUM(G16:I16) -> 426.67064 | K16: =+G16*$I$1 -> 528891.64 | L16: =+H16*$I$1 -> 153714.27 | M16: =+I16*$I$1 -> 258040.71 | N16: =SUM(K16:M16) -> 940646.62 | P16: =C16/$F$3 -> 0.016202913 | Q16: =D16/$F$4 -> 0.03447537 | R16: =E16/$F$5 -> 0.034061323
A17: 2319 | B17: LAURA | C17: 970988 | D17: 73471 | E17: 92582 | F17: =SUM(C17:E17) -> 1137041 | G17: =+C17/$F$3*$E$3 -> 239.6076 | H17: =+D17/$F$4*$E$4 -> 5.3537209 | I17: =+E17/$F$5*$E$5 -> 16.326221 | J17: =SUM(G17:I17) -> 261.28754 | K17: =+G17*$I$1 -> 528243.7 | L17: =+H17*$I$1 -> 11802.92 | M17: =+I17*$I$1 -> 35993.113 | N17: =SUM(K17:M17) -> 576039.73 | P17: =C17/$F$3 -> 0.016183063 | Q17: =D17/$F$4 -> 0.0026471844 | R17: =E17/$F$5 -> 0.0047510838
A18: 3600 | B18: HICKORY WIND | C18: 827739 | D18: 271795 | E18: 135897 | F18: =SUM(C18:E18) -> 1235431 | G18: =+C18/$F$3*$E$3 -> 204.2585 | H18: =+D18/$F$4*$E$4 -> 19.805291 | I18: =+E18/$F$5*$E$5 -> 23.964534 | J18: =SUM(G18:I18) -> 248.02833 | K18: =+G18*$I$1 -> 450312.38 | L18: =+H18*$I$1 -> 43663.141 | M18: =+I18*$I$1 -> 52832.69 | N18: =SUM(K18:M18) -> 546808.21 | P18: =C18/$F$3 -> 0.01379559 | Q18: =D18/$F$4 -> 0.0097928638 | R18: =E18/$F$5 -> 0.0069739047
A19: 3896 | B19: AMERICAN EAGLE | C19: 1952646 | D19: 625968 | E19: 395511 | F19: =SUM(C19:E19) -> 2974125 | G19: =+C19/$F$3*$E$3 -> 481.8482 | H19: =+D19/$F$4*$E$4 -> 45.613343 | I19: =+E19/$F$5*$E$5 -> 69.745739 | J19: =SUM(G19:I19) -> 597.20728 | K19: =+G19*$I$1 -> 1062292.2 | L19: =+H19*$I$1 -> 100560.09 | M19: =+I19*$I$1 -> 153762.85 | N19: =SUM(K19:M19) -> 1316615.1 | P19: =C19/$F$3 -> 0.032543958 | Q19: =D19/$F$4 -> 0.022553834 | R19: =E19/$F$5 -> 0.020296666
A20: 2565 | B20: VANGUARD | C20: 2340030 | D20: 110213 | E20: 238931 | F20: =SUM(C20:E20) -> 2689174 | G20: =+C20/$F$3*$E$3 -> 577.4417 | H20: =+D20/$F$4*$E$4 -> 8.0310549 | I20: =+E20/$F$5*$E$5 -> 42.133895 | J20: =SUM(G20:I20) -> 627.60666 | K20: =+G20*$I$1 -> 1273039.5 | L20: =+H20*$I$1 -> 17705.424 | M20: =+I20*$I$1 -> 92889.229 | N20: =SUM(K20:M20) -> 1383634.2 | P20: =C20/$F$3 -> 0.03900033 | Q20: =D20/$F$4 -> 0.0039710109 | R20: =E20/$F$5 -> 0.01226136
A21: 1755 | B21: ENTERPRISE | C21: 167048 | D21: 61131 | E21: 23547 | F21: =SUM(C21:E21) -> 251726 | G21: =+C21/$F$3*$E$3 -> 41.2219 | H21: =+D21/$F$4*$E$4 -> 4.4545237 | I21: =+E21/$F$5*$E$5 -> 4.1523571 | J21: =SUM(G21:I21) -> 49.82878 | K21: =+G21*$I$1 -> 90878.624 | L21: =+H21*$I$1 -> 9820.532 | M21: =+I21*$I$1 -> 9154.3695 | N21: =SUM(K21:M21) -> 109853.53 | O21: Moved from NP to SBS for 2026 | P21: =C21/$F$3 -> 0.0027841212 | Q21: =D21/$F$4 -> 0.0022025702 | R21: =E21/$F$5 -> 0.001208375
A22: =COUNT(A10:A20) -> 11 | B22: TOTAL | C22: =SUM(C10:C21) -> 16058147 | D22: =SUM(D10:D21) -> 6569492 | E22: =SUM(E10:E21) -> 4304318 | F22: =SUM(F10:F21) -> 26931957 | G22: =SUM(G10:G21) -> 3962.6175 | H22: =SUM(H10:H21) -> 478.70896 | I22: =SUM(I10:I21) -> 759.0379 | J22: =SUM(J10:J21) -> 5200.3643 | ... N22: =SUM(N10:N21) -> 11464827 | P22: =C22/$F$3 -> 0.26763461 | Q22: =D22/$F$4 -> 0.23670097 | R22: =E22/$F$5 -> 0.22088717
C23: =C22/$F$3 -> 0.26763461 | D23: =D22/$F$4 -> 0.23670097 | E23: =E22/$F$5 -> 0.22088717 | F23: =F22/$F$6 -> 0.25113452 | G23: =G22/E3 -> 0.26763461 | H23: =H22/E4 -> 0.23670097 | I23: =I22/E5 -> 0.22088717 | J23: =J22/E6 -> 0.25662046 | K23: =+K22/G3 -> 0.26763461 | L23: =+L22/G4 -> 0.23670097 | M23: =+M22/G5 -> 0.22088717 | N23: =N22/G6 -> 0.25662046
E25: check: | F25: =SUM(C22:E22) -> 26931957 | I25: check: | J25: =SUM(G22:I22) -> 5200.3643 | M25: check: | N25: =SUM(K22:M22) -> 11464827
A27: NORTH PACIFIC
C28: QS UNITS | G28: 2026 TAC - METRIC TONS | K28: 2026 TAC - POUNDS | P28: % CV Pool Harvest Allocation for Exhibit B
A29: LLP | B29: Vessel | C29: POP | D29: NR | E29: DUSKY | F29: TOTAL | G29: POP | H29: NR | I29: DUSKY | J29: TOTAL | K29: POP | L29: NR | M29: DUSKY | N29: TOTAL | P29: POP | Q29: NR | R29: Dusky
A30: 2487 | B30: NICHOLE | C30: 1345844 | D30: 796811 | E30: 820370 | F30: =SUM(C30:E30) -> 2963025 | G30: =+C30/$F$3*$E$3 -> 332.10961 | H30: =+D30/$F$4*$E$4 -> 58.062415 | I30: =+E30/$F$5*$E$5 -> 144.6668 | J30: =SUM(G30:I30) -> 534.83883 | K30: =+G30*$I$1 -> 732175.49 | L30: =+H30*$I$1 -> 128005.56 | M30: =+I30*$I$1 -> 318935.33 | N30: =SUM(K30:M30) -> 1179116.4 | O30: probably moving to SBS | P30: =C30/$F$3 -> 0.022430635 | Q30: =D30/$F$4 -> 0.028709364 | R30: =E30/$F$5 -> 0.0420994
A31: 1541 | B31: SEA MAC - MAGIC | C31: 1111437 | D31: 97033 | E31: 79146 | F31: =SUM(C31:E31) -> 1287616 | G31: =+C31/$F$3*$E$3 -> 274.26575 | H31: =+D31/$F$4*$E$4 -> 7.0706482 | I31: =+E31/$F$5*$E$5 -> 13.956872 | J31: =SUM(G31:I31) -> 295.29327 | K31: =+G31*$I$1 -> 604651.75 | L31: =+H31*$I$1 -> 15588.093 | M31: =+I31*$I$1 -> 30769.598 | N31: =SUM(K31:M31) -> 651009.44 | P31: =C31/$F$3 -> 0.018523869 | Q31: =D31/$F$4 -> 0.0034961311 | R31: =E31/$F$5 -> 0.0040615809
A32: 3785 | B32: SEA MAC | C32: 510284 | D32: 238904 | E32: 161211 | F32: =SUM(C32:E32) -> 910399 | G32: =+C32/$F$3*$E$3 -> 125.92115 | H32: =+D32/$F$4*$E$4 -> 17.408574 | I32: =+E32/$F$5*$E$5 -> 28.428489 | J32: =SUM(G32:I32) -> 171.75821 | K32: =+G32*$I$1 -> 277608.28 | L32: =+H32*$I$1 -> 38379.29 | M32: =+I32*$I$1 -> 62674.016 | N32: =SUM(K32:M32) -> 378661.59 | P32: =C32/$F$3 -> 0.0085046962 | Q32: =D32/$F$4 -> 0.0086077902 | R32: =E32/$F$5 -> 0.0082729578
A33: 2653 | B33: SEA MAC 2653 | C33: 194806 | D33: 233 | E33: 7609 | F33: =SUM(C33:E33) -> 202648 | G33: =+C33/$F$3*$E$3 -> 48.071652 | H33: =+D33/$F$4*$E$4 -> 0.016978358 | I33: =+E33/$F$5*$E$5 -> 1.3417966 | J33: =SUM(G33:I33) -> 49.430427 | K33: =+G33*$I$1 -> 105979.73 | L33: =+H33*$I$1 -> 37.430828 | M33: =+I33*$I$1 -> 2958.1517 | N33: =SUM(K33:M33) -> 108975.31 | P33: =C33/$F$3 -> 0.0032467525 | Q33: =D33/$F$4 -> 8.3950671e-06 | R33: =E33/$F$5 -> 0.00039047544
A34: 2973 | B34: CARAVELLE | C34: 1261813 | D34: 871860 | E34: 618497 | F34: =SUM(C34:E34) -> 2752170 | G34: =+C34/$F$3*$E$3 -> 311.37355 | H34: =+D34/$F$4*$E$4 -> 63.531122 | I34: =+E34/$F$5*$E$5 -> 109.06784 | J34: =SUM(G34:I34) -> 483.97251 | K34: =+G34*$I$1 -> 686460.36 | L34: =+H34*$I$1 -> 140061.98 | M34: =+I34*$I$1 -> 240453.14 | N34: =SUM(K34:M34) -> 1066975.5 | P34: =C34/$F$3 -> 0.021030125 | Q34: =D34/$F$4 -> 0.031413404 | R34: =E34/$F$5 -> 0.031739767
A35: 2535 | B35: TOPAZ | C35: 1982098 | D35: 1343344 | E35: 1060363 | F35: =SUM(C35:E35) -> 4385805 | G35: =+C35/$F$3*$E$3 -> 489.11597 | H35: =+D35/$F$4*$E$4 -> 97.887449 | I35: =+E35/$F$5*$E$5 -> 186.98797 | J35: =SUM(G35:I35) -> 773.9914 | K35: =+G35*$I$1 -> 1078314.9 | L35: =+H35*$I$1 -> 215804.63 | M35: =+I35*$I$1 -> 412237.43 | N35: =SUM(K35:M35) -> 1706356.9 | P35: =C35/$F$3 -> 0.033034822 | Q35: =D35/$F$4 -> 0.048401129 | R35: =E35/$F$5 -> 0.054415259
A36: 1590 | B36: ALASKA BEAUTY | C36: 1029074 | D36: 336623 | E36: 310881 | F36: =SUM(C36:E36) -> 1676578 | G36: =+C36/$F$3*$E$3 -> 253.94129 | H36: =+D36/$F$4*$E$4 -> 24.52921 | I36: =+E36/$F$5*$E$5 -> 54.8218 | J36: =SUM(G36:I36) -> 333.2923 | K36: =+G36*$I$1 -> 559844.05 | L36: =+H36*$I$1 -> 54077.587 | M36: =+I36*$I$1 -> 120861.24 | N36: =SUM(K36:M36) -> 734782.88 | P36: =C36/$F$3 -> 0.017151158 | Q36: =D36/$F$4 -> 0.012128638 | R36: =E36/$F$5 -> 0.015953659
A37: 2148 | B37: CAPT'N ART | C37: 337304 | D37: 4733 | E37: 5204 | F37: =SUM(C37:E37) -> 347241 | G37: =+C37/$F$3*$E$3 -> 83.235427 | H37: =+D37/$F$4*$E$4 -> 0.34488656 | I37: =+E37/$F$5*$E$5 -> 0.91769085 | J37: =SUM(G37:I37) -> 84.498005 | K37: =+G37*$I$1 -> 183502.49 | L37: =+H37*$I$1 -> 760.34382 | M37: =+I37*$I$1 -> 2023.1596 | N37: =SUM(K37:M37) -> 186285.99 | P37: =C37/$F$3 -> 0.0056217088 | Q37: =D37/$F$4 -> 0.00017053156 | R37: =E37/$F$5 -> 0.00026705667
A38: 3764 | B38: ALASKAN | C38: 400932 | D38: 7432 | E38: 18653 | F38: =SUM(C38:E38) -> 427017 | G38: =+C38/$F$3*$E$3 -> 98.936705 | H38: =+D38/$F$4*$E$4 -> 0.54155862 | I38: =+E38/$F$5*$E$5 -> 3.2893327 | J38: =SUM(G38:I38) -> 102.7676 | K38: =+G38*$I$1 -> 218117.84 | L38: =+H38*$I$1 -> 1193.931 | M38: =+I38*$I$1 -> 7251.7287 | N38: =SUM(K38:M38) -> 226563.5 | P38: =C38/$F$3 -> 0.0066821708 | Q38: =D38/$F$4 -> 0.00026777742 | R38: =E38/$F$5 -> 0.00095722675
A39: 1183 | B39: LESLIE LEE | C39: 1753708 | D39: 240585 | E39: 103879 | F39: =SUM(C39:E39) -> 2098172 | G39: =+C39/$F$3*$E$3 -> 432.7569 | H39: =+D39/$F$4*$E$4 -> 17.531066 | I39: =+E39/$F$5*$E$5 -> 18.318372 | J39: =SUM(G39:I39) -> 468.60634 | K39: =+G39*$I$1 -> 954064.52 | L39: =+H39*$I$1 -> 38649.338 | M39: =+I39*$I$1 -> 40385.049 | N39: =SUM(K39:M39) -> 1033098.9 | P39: =C39/$F$3 -> 0.029228339 | Q39: =D39/$F$4 -> 0.0086683572 | R39: =E39/$F$5 -> 0.0053308185
A40: =COUNT(A30:A39) -> 10 | B40: TOTAL | C40: =SUM(C30:C39) -> 9927300 | D40: =SUM(D30:D39) -> 3937558 | E40: =SUM(E30:E39) -> 3185813 | F40: =SUM(F30:F39) -> 17050671 | G40: =SUM(G30:G39) -> 2449.728 | H40: =SUM(H30:H39) -> 286.92391 | I40: =SUM(I30:I39) -> 561.79697 | J40: =SUM(J30:J39) -> 3298.4489 | ... N40: =SUM(N30:N39) -> 7271826.4 | P40: =C40/$F$3 -> 0.16545428 | Q40: =D40/$F$4 -> 0.14187152 | R40: =E40/$F$5 -> 0.1634882
C41: =C40/F3 -> 0.16545428 | D41: =D40/F4 -> 0.14187152 | E41: =E40/F5 -> 0.1634882 | F41: =F40/F6 -> 0.15899372 | G41: =G40/E3 -> 0.16545428 | H41: =H40/E4 -> 0.14187152 | I41: =I40/E5 -> 0.1634882 | J41: =J40/E6 -> 0.16276734 | K41: =+K40/G3 -> 0.16545428 | L41: =+L40/G4 -> 0.14187152 | M41: =+M40/G5 -> 0.1634882 | N41: =N40/G6 -> 0.16276734
E43: check: | F43: =SUM(C40:E40) -> 17050671 | I43: check: | J43: =SUM(G40:I40) -> 3298.4489 | M43: check: | N43: =SUM(K40:M40) -> 7271826.4
...

Sheet CV Secondary & PSC Alloc
A1: Secondary Species + Halibut PSC Allocations | K1: updated for 2026
A3: =IFERROR(__xludf.DUMMYFUNCTION("IMPORTRANGE(""https://docs.google.com/spreadsheets/d/1fpr4iXJjYPIWfqLVGaDLSDFHokxxaVbtvYkSxFtDSHM/edit#gid=783412060"", ""'CV Coop Sector Alloc'!A50:G63"")"),"Secondary Species + Halibut PSC - Metric Tons") -> Secondary Species + Halibut PSC - Metric Tons | L3: 2026 | M3: CV QS POOL
A4: =IFERROR(__xludf.DUMMYFUNCTION("""COMPUTED_VALUE"""),"Species") -> Species | B4: =IFERROR(__xludf.DUMMYFUNCTION("""COMPUTED_VALUE"""),"CV sector") -> CV sector | C4: =IFERROR(__xludf.DUMMYFUNCTION("""COMPUTED_VALUE"""),"SBS") -> SBS | D4: =IFERROR(__xludf.DUMMYFUNCTION("""COMPUTED_VALUE"""),"NP") -> NP | E4: =IFERROR(__xludf.DUMMYFUNCTION("""COMPUTED_VALUE"""),"OBSI") -> OBSI | F4: =IFERROR(__xludf.DUMMYFUNCTION("""COMPUTED_VALUE"""),"SOK") -> SOK | G4: =IFERROR(__xludf.DUMMYFUNCTION("""COMPUTED_VALUE"""),"Total") -> Total | L4: Issued QS Aggregate Total | M4: ='Alloc by Sector'!$D$22 -> 107241157
A5: =IFERROR(__xludf.DUMMYFUNCTION("""COMPUTED_VALUE"""),"Sablefish") -> Sablefish | B5: =IFERROR(__xludf.DUMMYFUNCTION("""COMPUTED_VALUE"""),374.7306) -> 374.7306 | C5: =IFERROR(__xludf.DUMMYFUNCTION("""COMPUTED_VALUE"""),93.22819009467231) -> 93.22819 | D5: =IFERROR(__xludf.DUMMYFUNCTION("""COMPUTED_VALUE"""),60.45941493570607) -> 60.459415 | E5: =IFERROR(__xludf.DUMMYFUNCTION("""COMPUTED_VALUE"""),82.51735617305769) -> 82.517356 | F5: =IFERROR(__xludf.DUMMYFUNCTION("""COMPUTED_VALUE"""),138.52563879656387) -> 138.52564 | G5: =IFERROR(__xludf.DUMMYFUNCTION("""COMPUTED_VALUE"""),374.7306) -> 374.7306
A6: =IFERROR(__xludf.DUMMYFUNCTION("""COMPUTED_VALUE"""),"Pacific Cod") -> Pacific Cod | B6: =IFERROR(__xludf.DUMMYFUNCTION("""COMPUTED_VALUE"""),550.440225) -> 550.44023 | C6: =IFERROR(__xludf.DUMMYFUNCTION("""COMPUTED_VALUE"""),136.94250197889954) -> 136.9425 | D6: =IFERROR(__xludf.DUMMYFUNCTION("""COMPUTED_VALUE"""),88.80858398160817) -> 88.808584 | E6: =IFERROR(__xludf.DUMMYFUNCTION("""COMPUTED_VALUE"""),121.20940243018057) -> 121.2094 | F6: =IFERROR(__xludf.DUMMYFUNCTION("""COMPUTED_VALUE"""),203.47973660931177) -> 203.47974 | G6: =IFERROR(__xludf.DUMMYFUNCTION("""COMPUTED_VALUE"""),550.440225) -> 550.44023
A7: =IFERROR(__xludf.DUMMYFUNCTION("""COMPUTED_VALUE"""),"Thornyhead") -> Thornyhead | B7: =IFERROR(__xludf.DUMMYFUNCTION("""COMPUTED_VALUE"""),46.256) -> 46.256 | C7: =IFERROR(__xludf.DUMMYFUNCTION("""COMPUTED_VALUE"""),11.507902373115948) -> 11.507902 | D7: =IFERROR(__xludf.DUMMYFUNCTION("""COMPUTED_VALUE"""),7.46298993801419) -> 7.4629899 | E7: =IFERROR(__xludf.DUMMYFUNCTION("""COMPUTED_VALUE"""),10.185778335532133) -> 10.185778 | F7: =IFERROR(__xludf.DUMMYFUNCTION("""COMPUTED_VALUE"""),17.09932935333773) -> 17.099329 | G7: =IFERROR(__xludf.DUMMYFUNCTION("""COMPUTED_VALUE"""),46.256) -> 46.256
A8: =IFERROR(__xludf.DUMMYFUNCTION("""COMPUTED_VALUE"""),"Halibut") -> Halibut | B8: =IFERROR(__xludf.DUMMYFUNCTION("""COMPUTED_VALUE"""),117.33749999999999) -> 117.3375 | C8: =IFERROR(__xludf.DUMMYFUNCTION("""COMPUTED_VALUE"""),29.192072265338386) -> 29.192072 | D8: =IFERROR(__xludf.DUMMYFUNCTION("""COMPUTED_VALUE"""),18.931351216096072) -> 18.931351 | E8: =IFERROR(__xludf.DUMMYFUNCTION("""COMPUTED_VALUE"""),25.83824294027805) -> 25.838243 | F8: =IFERROR(__xludf.DUMMYFUNCTION("""COMPUTED_VALUE"""),43.37583357828748) -> 43.375834 | G8: =IFERROR(__xludf.DUMMYFUNCTION("""COMPUTED_VALUE"""),117.33749999999998) -> 117.3375
A11: =IFERROR(__xludf.DUMMYFUNCTION("""COMPUTED_VALUE"""),"Secondary Species + Halibut PSC - Pounds") -> Secondary Species + Halibut PSC - Pounds
A12: =IFERROR(__xludf.DUMMYFUNCTION("""COMPUTED_VALUE"""),"Species") -> Species | B12: =IFERROR(__xludf.DUMMYFUNCTION("""COMPUTED_VALUE"""),"CV sector") -> CV sector | C12: =IFERROR(__xludf.DUMMYFUNCTION("""COMPUTED_VALUE"""),"SBS") -> SBS | D12: =IFERROR(__xludf.DUMMYFUNCTION("""COMPUTED_VALUE"""),"NP") -> NP | E12: =IFERROR(__xludf.DUMMYFUNCTION("""COMPUTED_VALUE"""),"OBSI") -> OBSI | F12: =IFERROR(__xludf.DUMMYFUNCTION("""COMPUTED_VALUE"""),"SOK") -> SOK | G12: =IFERROR(__xludf.DUMMYFUNCTION("""COMPUTED_VALUE"""),"Total") -> Total
A13: =IFERROR(__xludf.DUMMYFUNCTION("""COMPUTED_VALUE"""),"Sablefish") -> Sablefish | B13: =IFERROR(__xludf.DUMMYFUNCTION("""COMPUTED_VALUE"""),826138.5753719999) -> 826138.58 | C13: =IFERROR(__xludf.DUMMYFUNCTION("""COMPUTED_VALUE"""),205532.73244651646) -> 205532.73 | D13: =IFERROR(__xludf.DUMMYFUNCTION("""COMPUTED_VALUE"""),133290.03535555632) -> 133290.04 | E13: =IFERROR(__xludf.DUMMYFUNCTION("""COMPUTED_VALUE"""),181919.41376624643) -> 181919.41 | F13: =IFERROR(__xludf.DUMMYFUNCTION("""COMPUTED_VALUE"""),305396.3938036806) -> 305396.39 | G13: =IFERROR(__xludf.DUMMYFUNCTION("""COMPUTED_VALUE"""),826138.5753719998) -> 826138.58
A14: =IFERROR(__xludf.DUMMYFUNCTION("""COMPUTED_VALUE"""),"Pacific Cod") -> Pacific Cod | B14: =IFERROR(__xludf.DUMMYFUNCTION("""COMPUTED_VALUE"""),1213511.5288395002) -> 1213511.5 | C14: =IFERROR(__xludf.DUMMYFUNCTION("""COMPUTED_VALUE"""),301906.1787127215) -> 301906.18 | D14: =IFERROR(__xludf.DUMMYFUNCTION("""COMPUTED_VALUE"""),195789.18041753297) -> 195789.18 | E14: =IFERROR(__xludf.DUMMYFUNCTION("""COMPUTED_VALUE"""),267220.6727856247) -> 267220.67 | F14: =IFERROR(__xludf.DUMMYFUNCTION("""COMPUTED_VALUE"""),448595.49692362087) -> 448595.5 | G14: =IFERROR(__xludf.DUMMYFUNCTION("""COMPUTED_VALUE"""),1213511.5288395) -> 1213511.5
A15: =IFERROR(__xludf.DUMMYFUNCTION("""COMPUTED_VALUE"""),"Thornyhead") -> Thornyhead | B15: =IFERROR(__xludf.DUMMYFUNCTION("""COMPUTED_VALUE"""),101976.90272) -> 101976.9 | C15: =IFERROR(__xludf.DUMMYFUNCTION("""COMPUTED_VALUE"""),25370.551729818882) -> 25370.552 | D15: =IFERROR(__xludf.DUMMYFUNCTION("""COMPUTED_VALUE"""),16453.05687714484) -> 16453.057 | E15: =IFERROR(__xludf.DUMMYFUNCTION("""COMPUTED_VALUE"""),22455.77063408085) -> 22455.771 | F15: =IFERROR(__xludf.DUMMYFUNCTION("""COMPUTED_VALUE"""),37697.52347895542) -> 37697.523 | G15: =IFERROR(__xludf.DUMMYFUNCTION("""COMPUTED_VALUE"""),101976.90272) -> 101976.9
A16: =IFERROR(__xludf.DUMMYFUNCTION("""COMPUTED_VALUE"""),"Halibut") -> Halibut | B16: =IFERROR(__xludf.DUMMYFUNCTION("""COMPUTED_VALUE"""),258684.59924999997) -> 258684.6 | C16: =IFERROR(__xludf.DUMMYFUNCTION("""COMPUTED_VALUE"""),64357.42635761031) -> 64357.426 | D16: =IFERROR(__xludf.DUMMYFUNCTION("""COMPUTED_VALUE"""),41736.43551802972) -> 41736.436 | E16: =IFERROR(__xludf.DUMMYFUNCTION("""COMPUTED_VALUE"""),56963.50715099579) -> 56963.507 | F16: =IFERROR(__xludf.DUMMYFUNCTION("""COMPUTED_VALUE"""),95627.23022336414) -> 95627.23 | G16: =IFERROR(__xludf.DUMMYFUNCTION("""COMPUTED_VALUE"""),258684.59924999997) -> 258684.6 | M16: TOT % CV Pool column is used for the secondary species percentage for each vessel in the Exhibit B Harvest Schedule (% CV Pool Harvest Allocations)
A17: Tables above are linked from CV Coop Sector Alloc tab to calculate the allocations for each Coop LLP
A19: CV Cooperative Allocations by LLP
A20: SILVER BAY
A21: LLP | B21: Vessel | C21: QS UNITS | G21: TOT % CV POOL | H21: Secondary Species + Halibut in pounds
C22: POP | D22: NR | E22: DUSKY | F22: TOTAL | H22: Sablefish | I22: Pcod | J22: Thornyhd | K22: Halibut
A23: 2696 | B23: MAR PACIFICO | C23: 1973449 | D23: 1253570 | E23: 780343 | F23: =SUM(C23:E23) -> 4007362 | G23: =+F23/$M$4 -> 0.037367762 | H23: =+$B$13*G23 -> 30870.949 | I23: =+G23*$B$14 -> 45346.21 | J23: =+G23*$B$15 -> 3810.6486 | K23: =+G23*$B$16 -> 9666.4645
A24: 1554 | B24: CHELLISSA | C24: 510284 | D24: 238904 | E24: 161211 | F24: =SUM(C24:E24) -> 910399 | G24: =+F24/$M$4 -> 0.0084892687 | H24: =+$B$13*G24 -> 7013.3124 | I24: =+G24*$B$14 -> 10301.825 | J24: =+G24*$B$15 -> 865.70933 | K24: =+G24*$B$16 -> 2196.0431
A25: 2165 | B25: DAWN | C25: 1257125 | D25: 307669 | E25: 339446 | F25: =SUM(C25:E25) -> 1904240 | G25: =+F25/$M$4 -> 0.017756616 | H25: =+$B$13*G25 -> 14669.425 | I25: =+G25*$B$14 -> 21547.858 | J25: =+G25*$B$15 -> 1810.7647 | K25: =+G25*$B$16 -> 4593.363
A26: 1841 | B26: MAR DEL NORTE | C26: 1479627 | D26: 765284 | E26: 437036 | F26: =SUM(C26:E26) -> 2681947 | G26: =+F26/$M$4 -> 0.025008561 | H26: =+$B$13*G26 -> 20660.537 | I26: =+G26*$B$14 -> 30348.177 | J26: =+G26*$B$15 -> 2550.2956 | K26: =+G26*$B$16 -> 6469.3295
A27: 4851 | B27: PK FISH HOLDINGS | C27: 1100949 | D27: 608301 | E27: 260197 | F27: =SUM(C27:E27) -> 1969447 | G27: =+F27/$M$4 -> 0.018364656 | H27: =+$B$13*G27 -> 15171.751 | I27: =+G27*$B$14 -> 22285.722 | J27: =+G27*$B$15 -> 1872.7708 | K27: =+G27*$B$16 -> 4750.6538
A28: 3665 | B28: EVIE GRACE | C28: 2506083 | D28: 1296343 | E28: 775881 | F28: =SUM(C28:E28) -> 4578307 | G28: =+F28/$M$4 -> 0.042691697 | H28: =+$B$13*G28 -> 35269.258 | I28: =+G28*$B$14 -> 51806.867 | J28: =+G28*$B$15 -> 4353.567 | K28: =+G28*$B$16 -> 11043.685
A29: 3496 | B29: MiRoCo | C29: 972179 | D29: 956843 | E29: 663736 | F29: =SUM(C29:E29) -> 2592758 | G29: =+F29/$M$4 -> 0.024176893 | H29: =+$B$13*G29 -> 19973.464 | I29: =+G29*$B$14 -> 29338.939 | J29: =+G29*$B$15 -> 2465.4847 | K29: =+G29*$B$16 -> 6254.1899
A30: 2319 | B30: LAURA | C30: 970988 | D30: 73471 | E30: 92582 | F30: =SUM(C30:E30) -> 1137041 | G30: =+F30/$M$4 -> 0.010602655 | H30: =+$B$13*G30 -> 8759.2624 | I30: =+G30*$B$14 -> 12866.444 | J30: =+G30*$B$15 -> 1081.2259 | K30: =+G30*$B$16 -> 2742.7436
A31: 3600 | B31: HICKORY WIND | C31: 827739 | D31: 271795 | E31: 135897 | F31: =SUM(C31:E31) -> 1235431 | G31: =+F31/$M$4 -> 0.01152012 | H31: =+$B$13*G31 -> 9517.2155 | I31: =+G31*$B$14 -> 13979.798 | J31: =+G31*$B$15 -> 1174.7862 | K31: =+G31*$B$16 -> 2980.0776
A32: 3896 | B32: AMERICAN EAGLE | C32: 1952646 | D32: 625968 | E32: 395511 | F32: =SUM(C32:E32) -> 2974125 | G32: =+F32/$M$4 -> 0.027733056 | H32: =+$B$13*G32 -> 22911.347 | I32: =+G32*$B$14 -> 33654.383 | J32: =+G32*$B$15 -> 2828.1311 | K32: =+G32*$B$16 -> 7174.1144
A33: 2565 | B33: VANGUARD | C33: 2340030 | D33: 110213 | E33: 238931 | F33: =SUM(C33:E33) -> 2689174 | G33: =+F33/$M$4 -> 0.025075951 | H33: =+$B$13*G33 -> 20716.21 | I33: =+G33*$B$14 -> 30429.956 | J33: =+G33*$B$15 -> 2557.1678 | K33: =+G33*$B$16 -> 6486.7623
A34: 1755 | B34: ENTERPRISE | C34: 167048 | D34: 61131 | E34: 23547 | F34: =SUM(C34:E34) -> 251726 | G34: =+F34/$M$4 -> 0.0023472891 | H34: =+$B$13*G34 -> 1939.1861 | I34: =+G34*$B$14 -> 2848.4624 | J34: =+G34*$B$15 -> 239.36927 | K34: =+G34*$B$16 -> 607.20754 | L34: moving to sbs
A35: TOTAL | C35: =SUM(C23:C33) -> 15891099 | D35: =SUM(D23:D33) -> 6508361 | E35: =SUM(E23:E33) -> 4280771 | F35: =SUM(F23:F33) -> 26680231 | G35: =+F35/$M$4 -> 0.24878724 | H35: =SUM(H23:H33) -> 205532.73 | I35: =SUM(I23:I33) -> 301906.18 | J35: =SUM(J23:J33) -> 25370.552 | K35: =SUM(K23:K33) -> 64357.426
B36: =COUNTA(B23:B33) -> 11
F37: check: | G37: =SUM(G23:G33) -> 0.24878724
A38: NORTH PACIFIC
A39: LLP | B39: Vessel | C39: QS UNITS | G39: TOT % CV POOL | H39: Secondary Species + Halibut in pounds
C40: POP | D40: NR | E40: DUSKY | F40: TOTAL | H40: Sablefish | I40: Pcod | J40: Thornyhd | K40: Halibut
A41: 2487 | B41: NICHOLE | C41: 1345844 | D41: 796811 | E41: 820370 | F41: =SUM(C41:E41) -> 2963025 | G41: =+F41/$M$4 -> 0.027629551 | H41: =+$B$13*G41 -> 22825.838 | I41: =+G41*$B$14 -> 33528.778 | J41: =+G41*$B$15 -> 2817.576 | K41: =+G41*$B$16 -> 7147.3393 | L41: probably moving to sbs
A42: 1541 | B42: SEA MAC - MAGIC | C42: 1111437 | D42: 97033 | E42: 79146 | F42: =SUM(C42:E42) -> 1287616 | G42: =+F42/$M$4 -> 0.012006734 | H42: =+$B$13*G42 -> 9919.2258 | I42: =+G42*$B$14 -> 14570.31 | J42: =+G42*$B$15 -> 1224.4095 | K42: =+G42*$B$16 -> 3105.9571
A43: 3785 | B43: SEA MAC | C43: 510284 | D43: 238904 | E43: 161211 | F43: =SUM(C43:E43) -> 910399 | G43: =+F43/$M$4 -> 0.0084892687 | H43: =+$B$13*G43 -> 7013.3124 | I43: =+G43*$B$14 -> 10301.825 | J43: =+G43*$B$15 -> 865.70933 | K43: =+G43*$B$16 -> 2196.0431
A44: 2653 | B44: SEA MAC 2653 | C44: 194806 | D44: 233 | E44: 7609 | F44: =SUM(C44:E44) -> 202648 | G44: =+F44/$M$4 -> 0.0018896476 | H44: =+$B$13*G44 -> 1561.1108 | I44: =+G44*$B$14 -> 2293.1092 | J44: =+G44*$B$15 -> 192.70041 | K44: =+G44*$B$16 -> 488.82274
...

Sheet TAC Sector Allocations
A1: CGOA ROCKFISH SECTOR ALLOCATIONS | L1: 46024 | M1: Updated with Council Dec Specs Motion
L3: Instructions | T3: PRIMARY ROCKFISH ICA HISTORY
A4: Species | B4: TAC | C4: ICA | D4: TAC - ICA | E4: Entry Level (FG) | F4: TAC for Coop CQ | G4: Sector | H4: QS units in that sector | I4: % QS pool to sector | J4: TAC to sector | L4: 1. When you copy/paste the new Table 10 from the GOA specs in the GOA Other Allocations tab of the Specs and Allocations spreadsheet, if you keep the cell references in tact the new TAC, ICA, TAC minus ICA, and Entry Level allocations (brownish cells) will autofill in this sheet. Double check. Also update the Primary Rockfish ICA history table to the right. | U4: ICA's | V4: POP | W4: NR | X4: Dusky
L5: 2. Make sure your green "TAC for CQ" cells also match the "Allocation to the Rockfish Cooperpatives" column in Table 10 of the GOA Specs. | U5: 2012 | V5: 900 | W5: 125 | X5: 125
A6: POP | B6: =IFERROR(__xludf.DUMMYFUNCTION("IMPORTRANGE(""https://docs.google.com/spreadsheets/d/16o26avt11eNbQTdY8bgf8e4G4Mskqme1yI30mjRNa-0/edit#gid=1833521013"", ""'GOA Gfish Specs'!I49"")"),27156.0) -> 27156 | C6: 2800 | D6: =B6-C6 -> 24356 | E6: =IFERROR(__xludf.DUMMYFUNCTION("IMPORTRANGE(""https://docs.google.com/spreadsheets/d/16o26avt11eNbQTdY8bgf8e4G4Mskqme1yI30mjRNa-0/edit#gid=1833521013"", ""'GOA Other Alloc'!E16"")"),5.0) -> 5 | F6: =D6-E6 -> 24351 | G6: CV | H6: 62053356 | I6: =H6/H8 -> 0.60802728 | J6: =$F$6*I6 -> 14806.072 | L6: 3. The "QS units in sector and % QS pool to sector" columns never change and are protected cells so they can't be edited. | U6: 2013 | V6: 900 | W6: 125 | X6: 200
G7: CP | H7: 40003505 | I7: =H7/H8 -> 0.39197272 | J7: =$F$6*I7 -> 9544.9276 | L7: 4. The light yellow column "TAC to Sector" is "TAC for CQ" multipled by the "% QS Pool to sector" for each species and sector. It should automatically update when you put in the new TAC/ICA/Entry allocations but make sure. The green cells in that column are also a data check and should match the "TAC for CQ" for that species (if your formulas are working properly). | U7: 2014 | V7: 1200 | W7: 200 | X7: 200
G8: Total | H8: 102056861 | J8: =SUM(J6:J7) -> 24351 | U8: 2015 | V8: 2000 | W8: 200 | X8: 250
A9: NR | B9: =IFERROR(__xludf.DUMMYFUNCTION("IMPORTRANGE(""https://docs.google.com/spreadsheets/d/16o26avt11eNbQTdY8bgf8e4G4Mskqme1yI30mjRNa-0/edit#gid=1833521013"", ""'GOA Gfish Specs'!I55"")"),3549.0) -> 3549 | C9: 300 | D9: =IFERROR(__xludf.DUMMYFUNCTION("IMPORTRANGE(""https://docs.google.com/spreadsheets/d/16o26avt11eNbQTdY8bgf8e4G4Mskqme1yI30mjRNa-0/edit#gid=1833521013"", ""'GOA Other Alloc'!D17"")"),3380.0) -> 3380 | E9: =IFERROR(__xludf.DUMMYFUNCTION("IMPORTRANGE(""https://docs.google.com/spreadsheets/d/16o26avt11eNbQTdY8bgf8e4G4Mskqme1yI30mjRNa-0/edit#gid=1833521013"", ""'GOA Other Alloc'!E16"")"),5.0) -> 5 | F9: =D9-E9 -> 3375 | G9: CV | H9: 28632008 | I9: =H9/H11 -> 0.59923579 | J9: =$F$9*I9 -> 2022.4208 | L9: 5. Allocations of secondary species should also automatically update when new Table 12 is put into Specs. The CGOA TAC is multipled by the % of TAC to that sector. These percentages only change if the Council takes action. The percentages are included in Table 12. Doublecheck everything with Table 12. | U9: 2016 | V9: 1500 | W9: 300 | X9: 250
G10: CP | H10: 19148863 | I10: =H10/H11 -> 0.40076421 | J10: =$F$9*I10 -> 1352.5792 | L10: 6. The pink "TAC to Sector" cell for cod should match the calculation in the 2023 GOA Fed Cod Allocations tab table for RP cod (cell D7). However, you need to use the ROUND CGOA TAC mt with no decimals. Each year when the new CGOA TACs pull into the spreadsheet, round the whole mt CGOA TAC number and multiply it by the percentage cell for that sector and species. The pink column should have decimal places that should be correct. | U10: 2017 | V10: 2000 | W10: 300 | X10: 250
G11: Total | H11: 47780871 | J11: =SUM(J9:J10) -> 3375 | L11: 7. Allocation of Halibut PSC by sector also doesn't normally change so make sure it still matches. If it does change, you need to multiple the Halibut PSC by %PSC to sector by hand and then put "PSC to Sector" in the dark purple cells with just one decimal place. Don't make it a calculation and don't use extra decimals or the numbers won't match. | U11: 2018 | V11: 4000 | W11: 300 | X11: 250
A12: DUSKY | B12: =IFERROR(__xludf.DUMMYFUNCTION("IMPORTRANGE(""https://docs.google.com/spreadsheets/d/16o26avt11eNbQTdY8bgf8e4G4Mskqme1yI30mjRNa-0/edit#gid=1833521013"", ""'GOA Gfish Specs'!I63"")"),5527.0) -> 5527 | C12: 250 | D12: =IFERROR(__xludf.DUMMYFUNCTION("IMPORTRANGE(""https://docs.google.com/spreadsheets/d/16o26avt11eNbQTdY8bgf8e4G4Mskqme1yI30mjRNa-0/edit#gid=1833521013"", ""'GOA Other Alloc'!D18"")"),5568.0) -> 5568 | E12: 50 | F12: =D12-E12 -> 5518 | G12: CV | H12: 20078757 | I12: =H12/H14 -> 0.62274648 | J12: =$F$12*I12 -> 3436.3151 | U12: 2019 | V12: 3000 | W12: 300 | X12: 250
G13: CP | H13: 12163508 | I13: =H13/H14 -> 0.37725352 | J13: =$F$12*I13 -> 2081.6849 | U13: 2020 | V13: 3000 | W13: 300 | X13: 250
G14: Total | H14: 32242265 | J14: =SUM(J12:J13) -> 5518 | U14: 2021 | V14: 2500 | W14: 300 | X14: 250
A15: Total QS | D15: =SUM(D6:D14) -> 33304 | E15: =SUM(E6:E14) -> 60 | F15: =SUM(F6:F14) -> 33244 | G15: CV | H15: 110764121 | I15: =H15/H17 -> 0.60832669 | J15: =$F$15*I15 -> 20223.212 | U15: 2022 | V15: 2500 | W15: 300 | X15: 250
G16: CP | H16: 71315876 | I16: =H16/H17 -> 0.39167331 | J16: =$F$15*I16 -> 13020.788 | U16: 2023 | V16: 3000 | W16: 300 | X16: 250
G17: Total | H17: 182079997 | J17: =SUM(J15:J16) -> 33244 | U17: 2024 | V17: 3500 | W17: 300 | X17: 250
U18: 2025 | V18: 3500 | W18: 300 | X18: 250
U19: 2026 | V19: 2800 | W19: 300 | X19: 250
A20: Allocation of Secondary Rockfish Species TAC by Sector
A21: Species | B21: CGOA TAC | C21: % of CGOA TAC to Sector | E21: Sector | F21: TAC to sector
A22: Pacific Cod | B22: =IFERROR(__xludf.DUMMYFUNCTION("IMPORTRANGE(""https://docs.google.com/spreadsheets/d/16o26avt11eNbQTdY8bgf8e4G4Mskqme1yI30mjRNa-0/edit#gid=1014936405"", ""'GOA Fed Cod'!D5"")"),14447.25) -> 14447.25 | C22: 0.0381 | E22: CV (only) | F22: =B22*C22 -> 550.44023
A23: Sablefish | B23: =IFERROR(__xludf.DUMMYFUNCTION("IMPORTRANGE(""https://docs.google.com/spreadsheets/d/16o26avt11eNbQTdY8bgf8e4G4Mskqme1yI30mjRNa-0/edit#gid=1833521013"", ""'GOA Gfish Specs'!I63"")"),5527.0) -> 5527 | C23: 0.0678 | E23: CV | F23: =B23*C23 -> 374.7306
C24: 0.0351 | E24: CP | F24: =B23*C24 -> 193.9977
E25: Total | F25: =SUM(F23:F24) -> 568.7283
A26: Shortraker | B26: =IFERROR(__xludf.DUMMYFUNCTION("IMPORTRANGE(""https://docs.google.com/spreadsheets/d/16o26avt11eNbQTdY8bgf8e4G4Mskqme1yI30mjRNa-0/edit#gid=1833521013"", ""'GOA Gfish Specs'!I59"")"),189.0) -> 189 | C26: 0.4 | E26: CP (only) | F26: =B26*C26 -> 75.6 | H26: =B26*0.0972 -> 18.3708
A27: Rougheye | B27: =IFERROR(__xludf.DUMMYFUNCTION("IMPORTRANGE(""https://docs.google.com/spreadsheets/d/16o26avt11eNbQTdY8bgf8e4G4Mskqme1yI30mjRNa-0/edit#gid=1833521013"", ""'GOA Gfish Specs'!I68"")"),366.0) -> 366 | C27: 0.5887 | E27: CP (only) | F27: =B27*C27 -> 215.4642
A28: Thornyhead | B28: =IFERROR(__xludf.DUMMYFUNCTION("IMPORTRANGE(""https://docs.google.com/spreadsheets/d/16o26avt11eNbQTdY8bgf8e4G4Mskqme1yI30mjRNa-0/edit#gid=1833521013"", ""'GOA Gfish Specs'!I75"")"),590.0) -> 590 | C28: 0.0784 | E28: CV | F28: =B28*C28 -> 46.256
C29: 0.265 | E29: CP | F29: =B28*C29 -> 156.35
E30: Total | F30: =SUM(F28:F29) -> 202.606
A31: Notes: Only CVs receieve allocations of P. Cod and it is allocated from the CGOA B Season P. Cod TAC. Only CPs receive allocations of Shortraker and Rougheye.
A35: Allocation of Halibut PSC by Sector
A36: Species | B36: Halibut PSC | C36: % of PSC to Sector | E36: Sector | F36: PSC to Sector
A37: Halibut | B37: 134.1 | C37: 0.875 | E37: CV | F37: =B37*C37 -> 117.3375
B38: 84.7 | C38: 0.875 | E38: CP | F38: =B38*C38 -> 74.1125
B39: =SUM(B37:B38) -> 218.8 | E39: Total | F39: =SUM(F37:F38) -> 191.45
A40: Note: Halibut PSC limits for RP do not change. Set in Regulation.

Sheet CV Coop Sector Alloc
A1: CV Coop Sector Allocations | E1: NOT UPDATED FOR 2023 | I1: 2204.62 | K1: Needs to be updated for 2026
A3: Rockfish QS Units | I3: 2025 Allocations (mt)
A4: CV SECTOR | B4: POP | C4: NR | D4: Dusky | E4: TOTAL | I4: CV SECTOR | J4: POP | K4: NR | L4: DUSKY | M4: SABLE | N4: COD | O4: THORNY | P4: HALIBUT | R4: CV Co-op | S4: POP (mt) | T4: POP (% of Total) | U4: NR (mt) | V4: NR (% of Total) | W4: Dusky (mt) | X4: Dusky (% of Total) | Y4: Total 2025 Rockfish (mt) | Z4: % of Total
A5: Silver Bay | B5: ='CV Coop LLP Primary Alloc'!C22 -> 16058147 | C5: ='CV Coop LLP Primary Alloc'!D22 -> 6569492 | D5: ='CV Coop LLP Primary Alloc'!E22 -> 4304318 | E5: =SUM(B5:D5) -> 26931957 | I5: SBS | J5: 3978.241 | K5: 474.254 | L5: 754.885 | M5: 164.359 | N5: 145.774 | O5: 11.507 | P5: 29.182 | R5: SBS | S5: =J5 -> 3978.241 | T5: =S5/$S$10 -> 0.2648505 | U5: =K5 -> 474.254 | V5: =U5/$U$10 -> 0.23449839 | W5: =L5 -> 754.885 | X5: =W5/$W$10 -> 0.21967877 | Y5: =SUM(J5:L5) -> 5207.38 | Z5: =Y5/$Y$10 -> 0.2542736
A6: North Pacific | B6: ='CV Coop LLP Primary Alloc'!C40 -> 9927300 | C6: ='CV Coop LLP Primary Alloc'!D40 -> 3937558 | D6: ='CV Coop LLP Primary Alloc'!E40 -> 3185813 | E6: =SUM(B6:D6) -> 17050671 | I6: North Pacific | J6: 2527.059 | K6: 291.378 | L6: 565.949 | M6: 106.588 | N6: 94.536 | O6: 7.462 | P6: 18.925 | R6: North Pacific | S6: =J6 -> 2527.059 | T6: =S6/$S$10 -> 0.16823839 | U6: =K6 -> 291.378 | V6: =U6/$U$10 -> 0.144074 | W6: =L6 -> 565.949 | X6: =W6/$W$10 -> 0.16469658 | Y6: =SUM(J6:L6) -> 3384.386 | Z6: =Y6/$Y$10 -> 0.16525777
A7: OBSI | B7: ='CV Coop LLP Primary Alloc'!C57 -> 12462620 | C7: ='CV Coop LLP Primary Alloc'!D57 -> 6418765 | D7: ='CV Coop LLP Primary Alloc'!E57 -> 4733598 | E7: =SUM(B7:D7) -> 23614983 | I7: OBSI | J7: 3119.942 | K7: 467.725 | L7: 834.738 | M7: 145.476 | N7: 129.026 | O7: 10.185 | P7: 25.829 | R7: OBSI | S7: =J7 -> 3119.942 | T7: =S7/$S$10 -> 0.20770944 | U7: =K7 -> 467.725 | V7: =U7/$U$10 -> 0.23127008 | W7: =L7 -> 834.738 | X7: =W7/$W$10 -> 0.24291675 | Y7: =SUM(J7:L7) -> 4422.405 | Z7: =Y7/$Y$10 -> 0.21594369
A8: SOK | B8: ='CV Coop LLP Primary Alloc'!C80 -> 21552195 | C8: ='CV Coop LLP Primary Alloc'!D80 -> 10828579 | D8: ='CV Coop LLP Primary Alloc'!E80 -> 7262772 | E8: =SUM(B8:D8) -> 39643546 | I8: SOK | J8: 5395.462 | K8: 789.062 | L8: 1280.741 | M8: 244.218 | N8: 216.602 | O8: 17.099 | P8: 43.361 | R8: SOK | S8: =J8 -> 5395.462 | T8: =S8/$S$10 -> 0.35920167 | U8: =K8 -> 789.062 | V8: =U8/$U$10 -> 0.39015753 | W8: =L8 -> 1280.741 | X8: =W8/$W$10 -> 0.3727079 | Y8: =SUM(J8:L8) -> 7465.265 | Z8: =Y8/$Y$10 -> 0.36452493
A9: Pacific | B9: 0 | C9: 0 | D9: 0 | E9: 0 | I9: Pacific | J9: 0 | K9: 0 | L9: 0 | M9: 0 | N9: 0 | O9: 0 | P9: 0 | R9: Pacific | S9: =J9 -> 0 | T9: =S9/$S$10 -> 0 | U9: =K9 -> 0 | V9: =U9/$U$10 -> 0 | W9: =L9 -> 0 | X9: =W9/$W$10 -> 0 | Y9: =SUM(J9:L9) -> 0 | Z9: =Y9/$Y$10 -> 0
A10: Total | B10: =SUM(B5:B9) -> 60000262 | C10: =SUM(C5:C9) -> 27754394 | D10: =SUM(D5:D9) -> 19486501 | E10: =SUM(E5:E9) -> 107241157 | I10: Total | J10: =SUM(J5:J9) -> 15020.704 | K10: =SUM(K5:K9) -> 2022.419 | L10: =SUM(L5:L9) -> 3436.313 | M10: =SUM(M5:M9) -> 660.641 | N10: =SUM(N5:N9) -> 585.938 | O10: =SUM(O5:O9) -> 46.253 | P10: =SUM(P5:P9) -> 117.297 | R10: Total | S10: =SUM(S5:S9) -> 15020.704 | T10: =SUM(T5:T9) -> 1 | U10: =SUM(U5:U9) -> 2022.419 | V10: =SUM(V5:V9) -> 1 | W10: =SUM(W5:W9) -> 3436.313 | X10: =SUM(X5:X9) -> 1 | Y10: =SUM(Y5:Y9) -> 20479.436 | Z10: =SUM(Z5:Z9) -> 1
A12: Table 6. In Allocations Doc:
A13: SBS CV Cooperative | I13: 2025 Allocations (lbs) | R13: DATA CHECK WITH NMFS
A14: SPECIES | B14: CV sector TAC | C14: SBS QS | D14: TOTAL QS POOL | E14: % OF TAC | F14: MT | G14: LBS | I14: CV SECTOR | J14: POP | K14: NR | L14: DUSKY | M14: SABLE | N14: COD | O14: THORNY | P14: HALIBUT | R14: 2025 | S14: NMFS | T14: AGDB | U14: Diff
A15: POP | B15: ='CV Coop LLP Primary Alloc'!E3 -> 14806.072 | C15: =+B5 -> 16058147 | D15: =$B$10 -> 60000262 | E15: =+C15/D15 -> 0.26763461 | F15: =+E15*B15 -> 3962.6175 | G15: =+F15*$I$1 -> 8736065.7 | I15: SBS | J15: =J5*2204.62 -> 8770509.7 | K15: =K5*2204.62 -> 1045549.9 | L15: =L5*2204.62 -> 1664234.6 | M15: =M5*2204.62 -> 362349.14 | N15: =N5*2204.62 -> 321376.28 | O15: =O5*2204.62 -> 25368.562 | P15: =P5*2204.62 -> 64335.221 | R15: POP | S15: 15020.704 | T15: =J10 -> 15020.704 | U15: =S15-T15 -> 0
A16: NR | B16: ='CV Coop LLP Primary Alloc'!E4 -> 2022.4208 | C16: =+C5 -> 6569492 | D16: =$C$10 -> 27754394 | E16: =+C16/D16 -> 0.23670097 | F16: =+E16*B16 -> 478.70896 | G16: =+F16*$I$1 -> 1055371.4 | I16: North Pacific | J16: =J6*2204.62 -> 5571204.8 | K16: =K6*2204.62 -> 642377.77 | L16: =L6*2204.62 -> 1247702.5 | M16: =M6*2204.62 -> 234986.04 | N16: =N6*2204.62 -> 208415.96 | O16: =O6*2204.62 -> 16450.874 | P16: =P6*2204.62 -> 41722.433 | R16: Northern | S16: 2022.419 | T16: =K10 -> 2022.419 | U16: =S16-T16 -> 0
A17: Dusky | B17: ='CV Coop LLP Primary Alloc'!E5 -> 3436.3151 | C17: =+D5 -> 4304318 | D17: =$D$10 -> 19486501 | E17: =+C17/D17 -> 0.22088717 | F17: =+E17*B17 -> 759.0379 | G17: =+F17*$I$1 -> 1673390.1 | I17: OBSI | J17: =J7*2204.62 -> 6878286.5 | K17: =K7*2204.62 -> 1031155.9 | L17: =L7*2204.62 -> 1840280.1 | M17: =M7*2204.62 -> 320719.3 | N17: =N7*2204.62 -> 284453.3 | O17: =O7*2204.62 -> 22454.055 | P17: =P7*2204.62 -> 56943.13 | R17: Dusky | S17: 3436.314 | T17: =L10 -> 3436.313 | U17: =S17-T17 -> 0.001
A18: Total | B18: =SUM(B15:B17) -> 20264.808 | C18: =SUM(C15:C17) -> 26931957 | D18: =SUM(D15:D17) -> 107241157 | E18: =+C18/D18 -> 0.25113452 | F18: =SUM(F15:F17) -> 5200.3643 | G18: =+F18*$I$1 -> 11464827 | I18: SOK | J18: =J8*2204.62 -> 11894943 | K18: =K8*2204.62 -> 1739581.9 | L18: =L8*2204.62 -> 2823547.2 | M18: =M8*2204.62 -> 538407.89 | N18: =N8*2204.62 -> 477525.1 | O18: =O8*2204.62 -> 37696.797 | P18: =P8*2204.62 -> 95594.528 | R18: Sablefish | S18: 660.641 | T18: =M10 -> 660.641 | U18: =S18-T18 -> 0
A19: NP CV Cooperative | I19: Pacific | J19: =J9*2204.62 -> 0 | K19: =K9*2204.62 -> 0 | L19: =L9*2204.62 -> 0 | M19: =M9*2204.62 -> 0 | N19: =N9*2204.62 -> 0 | O19: =O9*2204.62 -> 0 | P19: =P9*2204.62 -> 0 | R19: Pacific Cod | S19: 585.938 | T19: =N10 -> 585.938 | U19: =S19-T19 -> 0
I20: Total | J20: =SUM(J15:J19) -> 33114944 | K20: =SUM(K15:K19) -> 4458665.4 | L20: =SUM(L15:L19) -> 7575764.4 | M20: =SUM(M15:M19) -> 1456462.4 | N20: =SUM(N15:N19) -> 1291770.6 | O20: =SUM(O15:O19) -> 101970.29 | P20: =SUM(P15:P19) -> 258595.31 | R20: Thornyhd | S20: 46.254 | T20: =O10 -> 46.253 | U20: =S20-T20 -> 0.001
A21: SPECIES | B21: CV sector TAC | C21: NP QS | D21: TOTAL QS POOL | E21: % OF TAC | F21: MT | G21: LBS | R21: Halibut | S21: 117.298 | T21: =P10 -> 117.297 | U21: =S21-T21 -> 0.001
A22: POP | B22: =+B15 -> 14806.072 | C22: =+B6 -> 9927300 | D22: =$B$10 -> 60000262 | E22: =+C22/D22 -> 0.16545428 | F22: =+E22*B22 -> 2449.728 | G22: =+F22*$I$1 -> 5400719.4 | J22: 40% Processing Cap | R22: Grand Total | S22: =SUM(S15:S21) -> 21889.568 | T22: =SUM(T15:T21) -> 21889.565 | U22: =S22-T22 -> 0.003
A23: NR | B23: =+B16 -> 2022.4208 | C23: =+C6 -> 3937558 | D23: =$C$10 -> 27754394 | E23: =+C23/D23 -> 0.14187152 | F23: =+E23*B23 -> 286.92391 | G23: =+F23*$I$1 -> 632558.18 | J23: =SUM(J20:L20)*0.4 -> 18059750 | K23: =M20*0.4 -> 582584.94 | L23: =N20*0.4 -> 516708.25 | R23: Numbers get plugged into NMFS column once we have them from Steve Whitney to match to ours.
A24: Dusky | B24: =+B17 -> 3436.3151 | C24: =+D6 -> 3185813 | D24: =$D$10 -> 19486501 | E24: =+C24/D24 -> 0.1634882 | F24: =+E24*B24 -> 561.79697 | G24: =+F24*$I$1 -> 1238548.8 | J24: RF | K24: Sable | L24: Cod
A25: Total | B25: =SUM(B22:B24) -> 20264.808 | C25: =SUM(C22:C24) -> 17050671 | D25: =SUM(D22:D24) -> 107241157 | E25: =+C25/D25 -> 0.15899372 | F25: =SUM(F22:F24) -> 3298.4489 | G25: =+F25*$I$1 -> 7271826.4 | J25: 8% POP Vessel Harvest Cap
A26: OBI CV Cooperative | J26: =J20*0.08 -> 2649195.6
A28: SPECIES | B28: CV sector TAC | C28: OBI QS | D28: TOTAL QS POOL | E28: % OF TAC | F28: MT | G28: LBS
A29: POP | B29: =+B22 -> 14806.072 | C29: =+B7 -> 12462620 | D29: =$B$10 -> 60000262 | E29: =+C29/D29 -> 0.20770943 | F29: =+E29*B29 -> 3075.3608 | G29: =+F29*$I$1 -> 6780001.9
A30: NR | B30: =+B23 -> 2022.4208 | C30: =+C7 -> 6418765 | D30: =$C$10 -> 27754394 | E30: =+C30/D30 -> 0.23127023 | F30: =+E30*B30 -> 467.72572 | G30: =+F30*$I$1 -> 1031157.5
A31: Dusky | B31: =+B24 -> 3436.3151 | C31: =+D7 -> 4733598 | D31: =$D$10 -> 19486501 | E31: =+C31/D31 -> 0.24291678 | F31: =+E31*B31 -> 834.73858 | G31: =+F31*$I$1 -> 1840281.4
A32: Total | B32: =SUM(B29:B31) -> 20264.808 | C32: =SUM(C29:C31) -> 23614983 | D32: =SUM(D29:D31) -> 107241157 | E32: =+C32/D32 -> 0.22020448 | F32: =SUM(F29:F31) -> 4377.8251 | G32: =+F32*$I$1 -> 9651440.8
A33: SOK CV Cooperative
A35: SPECIES | B35: CV sector TAC | C35: SOK QS | D35: TOTAL QS POOL | E35: % OF TAC | F35: MT | G35: LBS
A36: POP | B36: =+B29 -> 14806.072 | C36: =+B8 -> 21552195 | D36: =$B$10 -> 60000262 | E36: =+C36/D36 -> 0.35920168 | F36: =+E36*B36 -> 5318.3661 | G36: =+F36*$I$1 -> 11724976
A37: NR | B37: =+B30 -> 2022.4208 | C37: =+C8 -> 10828579 | D37: =$C$10 -> 27754394 | E37: =+C37/D37 -> 0.39015728 | F37: =+E37*B37 -> 789.0622 | G37: =+F37*$I$1 -> 1739582.3
A38: Dusky | B38: =+B31 -> 3436.3151 | C38: =+D8 -> 7262772 | D38: =$D$10 -> 19486501 | E38: =+C38/D38 -> 0.37270786 | F38: =+E38*B38 -> 1280.7416 | G38: =+F38*$I$1 -> 2823548.6
A39: Total | B39: =SUM(B36:B38) -> 20264.808 | C39: =SUM(C36:C38) -> 39643546 | D39: =SUM(D36:D38) -> 107241157 | E39: =+C39/D39 -> 0.36966727 | F39: =SUM(F36:F38) -> 7388.1699 | G39: =+F39*$I$1 -> 16288107
A42: Pacific CV coop
A43: SPECIES | B43: CV sector TAC | C43: Pacific QS | D43: TOTAL QS POOL | E43: % OF TAC | F43: MT | G43: LBS
A44: POP | B44: =+#REF! -> #REF! | C44: =+B9 -> 0 | D44: =$B$10 -> 60000262 | E44: =+C44/D44 -> 0 | F44: =+E44*B44 -> #REF! | G44: =+F44*$I$1 -> #REF!
A45: NR | B45: =+#REF! -> #REF! | C45: =+C9 -> 0 | D45: =$C$10 -> 27754394 | E45: =+C45/D45 -> 0 | F45: =+E45*B45 -> #REF! | G45: =+F45*$I$1 -> #REF!
A46: Dusky | B46: =+#REF! -> #REF! | C46: =+D9 -> 0 | D46: =$D$10 -> 19486501 | E46: =+C46/D46 -> 0 | F46: =+E46*B46 -> #REF! | G46: =+F46*$I$1 -> #REF!
...

Sheet Alloc by Sector
A1: ALLOCATION TO SECTOR | G1: This tab doesn't get updated; it stays the same unless there is a regulatory change.
A3: PRIMARY RF | B3: SECTOR | C3: QS UNITS | D3: TOTAL UNITS | E3: % BY SECTOR
A4: POP | B4: CV | C4: ='TAC Sector Allocations'!H6 -> 62053356 | D4: ='TAC Sector Allocations'!H8 -> 102056861 | E4: =+C4/D4 -> 0.60802728
A5: POP | B5: CP | C5: ='TAC Sector Allocations'!H7 -> 40003505 | D5: ='TAC Sector Allocations'!H8 -> 102056861 | E5: =+C5/D5 -> 0.39197272 | L5: NMFS 4-11-12
A6: NR | B6: CV | C6: ='TAC Sector Allocations'!H9 -> 28632008 | D6: ='TAC Sector Allocations'!H11 -> 47780871 | E6: =+C6/D6 -> 0.59923579 | L6: Sector | M6: Sum of Quota Share
A7: NR | B7: CP | C7: ='TAC Sector Allocations'!H10 -> 19148863 | D7: ='TAC Sector Allocations'!H11 -> 47780871 | E7: =+C7/D7 -> 0.40076421 | L7: CP | M7: 71315876
A8: DUSKY | B8: CV | C8: ='TAC Sector Allocations'!H12 -> 20078757 | D8: ='TAC Sector Allocations'!H14 -> 32242265 | E8: =+C8/D8 -> 0.62274648 | L8: Northern Rockfish | M8: 19148863
A9: DUSKY | B9: CP | C9: ='TAC Sector Allocations'!H13 -> 12163508 | D9: ='TAC Sector Allocations'!H14 -> 32242265 | E9: =+C9/D9 -> 0.37725352 | L9: Pacific Ocean Perch | M9: 40003505
A10: TOTAL | B10: CV | C10: =+C6+C4+C8 -> 110764121 | D10: =+D6+D4+D8 -> 182079997 | E10: =+C10/D10 -> 0.60832669 | L10: Pelagic Shelf Rockfish | M10: 12163508
A11: TOTAL | B11: CP | C11: =+C7+C5+C9 -> 71315876 | D11: =+D7+D5+D9 -> 182079997 | E11: =+C11/D11 -> 0.39167331 | L11: CV | M11: 107241157
L12: Northern Rockfish | M12: 27754394
L13: Pacific Ocean Perch | M13: 60000262
A14: Category | B14: Species | C14: CP | D14: CV | E14: % CV | F14: % CP | L14: Pelagic Shelf Rockfish | M14: 19486501
A15: QS pool denominators | B15: POP | C15: =C5 -> 40003505 | D15: =C4 -> 62053356 | E15: =D15/(C15+D15) -> 0.60802728 | F15: =C15/(C15+D15) -> 0.39197272 | L15: Grand Total | M15: 178557033
A16: QS pool denominators | B16: NR | C16: =C7 -> 19148863 | D16: =C6 -> 28632008 | E16: =D16/(C16+D16) -> 0.59923579 | F16: =C16/(C16+D16) -> 0.40076421
A17: QS pool denominators | B17: DUSKY | C17: =C9 -> 12163508 | D17: =C8 -> 20078757 | E17: =D17/(C17+D17) -> 0.62274648 | F17: =C17/(C17+D17) -> 0.37725352
A18: QS pool denominators | B18: Total | C18: =SUM(C15:C17) -> 71315876 | D18: =SUM(D15:D17) -> 110764121 | E18: =D18/(C18+D18) -> 0.60832669 | F18: =C18/(C18+D18) -> 0.39167331 | M18: =M11*0.04 -> 4289646.3
A19: Issued QS aggregate total | B19: POP | C19: 40003505 | D19: =59919410+80852 -> 60000262 | E19: =D19/(C19+D19) -> 0.59998002 | F19: =C19/(C19+D19) -> 0.40001998 | H19: Link to Table at top of CV Coop LLP Primary Allocations (CV QS Pool)
A20: Issued QS aggregate total | B20: NR | C20: 19148863 | D20: 27754394 | E20: =D20/(C20+D20) -> 0.59173703 | F20: =C20/(C20+D20) -> 0.40826297
A21: Issued QS aggregate total | B21: DUSKY | C21: 12163508 | D21: 19486501 | E21: =D21/(C21+D21) -> 0.61568706 | F21: =C21/(C21+D21) -> 0.38431294
A22: Issued QS aggregate total | B22: Total | C22: =SUM(C19:C21) -> 71315876 | D22: =SUM(D19:D21) -> 107241157 | E22: =D22/(C22+D22) -> 0.6005989 | F22: =C22/(C22+D22) -> 0.3994011 | G22: POP Revised April 2, 2012
A23: Difference | B23: NR | C23: 0 | D23: =D16-D20 -> 877614
A24: Difference | B24: DUSKY | C24: 0 | D24: =D17-D21 -> 592256
A25: Difference | B25: POP | C25: 0 | D25: =D15-D19 -> 2053094
A26: Difference | B26: Total | C26: 0 | D26: =D18-D22 -> 3522964

Sheet Exhibit B Harvest Schedule
A1: Exhibit B - Harvest Schedules | G1: These tables are compiled via links from combined sections of tables in the CV Coop LLP Primary Alloc and the CV Secondary & PSC Alloc tabs. They should automatically update each year after LLP movements between coops are made. This is the source for Exhibit B - Harvest Schedule of each coop's membership agreement, which are included in each coop's CQ Permit Allocation each March. Note Member column is hand typed, refer to Membership Sheet but they are not necessarily listed in same order. Leave order the same in this spreadsheet. Everything should be double checked each year to make sure it's still linking to current spreadsheet and that members are still lined up with the appropriate vessel, LLP No and % of CV pool) | O1: Updated and proofed for 2025 on 2/20
A3: Silver Bay Seafoods
A4: MEMBER INFORMATION | D4: HARVEST ALLOCATIONS (% of CV POOL)
A5: Member | B5: LLP No. | C5: Vessel | D5: POP | E5: Northern | F5: Dusky | G5: Sablefish | H5: Pacific Cod | I5: Thornyhead | J5: Halibut PSC
A6: MAR PACIFICO, INC | B6: =IFERROR(__xludf.DUMMYFUNCTION("IMPORTRANGE(""https://docs.google.com/spreadsheets/d/1fpr4iXJjYPIWfqLVGaDLSDFHokxxaVbtvYkSxFtDSHM/edit#gid=1391174979"", ""'CV Coop LLP Primary Alloc'!A10:B21"")"),2696.0) -> 2696 | C6: =IFERROR(__xludf.DUMMYFUNCTION("""COMPUTED_VALUE"""),"MAR PACIFICO") -> MAR PACIFICO | D6: =IFERROR(__xludf.DUMMYFUNCTION("IMPORTRANGE(""https://docs.google.com/spreadsheets/d/1fpr4iXJjYPIWfqLVGaDLSDFHokxxaVbtvYkSxFtDSHM/edit#gid=1391174979"", ""'CV Coop LLP Primary Alloc'!P10:R21"")"),0.03289067304406104) -> 0.032890673 | E6: =IFERROR(__xludf.DUMMYFUNCTION("""COMPUTED_VALUE"""),0.045166541917650946) -> 0.045166542 | F6: =IFERROR(__xludf.DUMMYFUNCTION("""COMPUTED_VALUE"""),0.04004531136708432) -> 0.040045311 | G6: =IFERROR(__xludf.DUMMYFUNCTION("IMPORTRANGE(""https://docs.google.com/spreadsheets/d/1fpr4iXJjYPIWfqLVGaDLSDFHokxxaVbtvYkSxFtDSHM/edit#gid=1392452204"", ""'CV Secondary & PSC Alloc'!G23:G34"")"),0.03736776170738255) -> 0.037367762 | H6: =G6 -> 0.037367762 | I6: =G6 -> 0.037367762 | J6: =G6 -> 0.037367762
A7: CHELLISSA FISHERIES, LLC | B7: =IFERROR(__xludf.DUMMYFUNCTION("""COMPUTED_VALUE"""),1554.0) -> 1554 | C7: =IFERROR(__xludf.DUMMYFUNCTION("""COMPUTED_VALUE"""),"CHELLISSA") -> CHELLISSA | D7: =IFERROR(__xludf.DUMMYFUNCTION("""COMPUTED_VALUE"""),0.008504696196159943) -> 0.0085046962 | E7: =IFERROR(__xludf.DUMMYFUNCTION("""COMPUTED_VALUE"""),0.008607790175494375) -> 0.0086077902 | F7: =IFERROR(__xludf.DUMMYFUNCTION("""COMPUTED_VALUE"""),0.008272957777283875) -> 0.0082729578 | G7: =IFERROR(__xludf.DUMMYFUNCTION("""COMPUTED_VALUE"""),0.008489268723574103) -> 0.0084892687 | H7: =G7 -> 0.0084892687 | I7: =G7 -> 0.0084892687 | J7: =G7 -> 0.0084892687
A8: DAWN FISHERIES LLC | B8: =IFERROR(__xludf.DUMMYFUNCTION("""COMPUTED_VALUE"""),2165.0) -> 2165 | C8: =IFERROR(__xludf.DUMMYFUNCTION("""COMPUTED_VALUE"""),"DAWN") -> DAWN | D8: =IFERROR(__xludf.DUMMYFUNCTION("""COMPUTED_VALUE"""),0.02095199184296895) -> 0.020951992 | E8: =IFERROR(__xludf.DUMMYFUNCTION("""COMPUTED_VALUE"""),0.011085415880454821) -> 0.011085416 | F8: =IFERROR(__xludf.DUMMYFUNCTION("""COMPUTED_VALUE"""),0.01741954597184995) -> 0.017419546 | G8: =IFERROR(__xludf.DUMMYFUNCTION("""COMPUTED_VALUE"""),0.017756615587427874) -> 0.017756616 | H8: =G8 -> 0.017756616 | I8: =G8 -> 0.017756616 | J8: =G8 -> 0.017756616
A9: NORTH SEA FISHERIES, LLC | B9: =IFERROR(__xludf.DUMMYFUNCTION("""COMPUTED_VALUE"""),1841.0) -> 1841 | C9: =IFERROR(__xludf.DUMMYFUNCTION("""COMPUTED_VALUE"""),"MAR DEL NORTE") -> MAR DEL NORTE | D9: =IFERROR(__xludf.DUMMYFUNCTION("""COMPUTED_VALUE"""),0.02466034231650522) -> 0.024660342 | E9: =IFERROR(__xludf.DUMMYFUNCTION("""COMPUTED_VALUE"""),0.027573435759397233) -> 0.027573436 | F9: =IFERROR(__xludf.DUMMYFUNCTION("""COMPUTED_VALUE"""),0.02242762823351406) -> 0.022427628 | G9: =IFERROR(__xludf.DUMMYFUNCTION("""COMPUTED_VALUE"""),0.025008560845720826) -> 0.025008561 | H9: =G9 -> 0.025008561 | I9: =G9 -> 0.025008561 | J9: =G9 -> 0.025008561
A10: PK FISHERIES HOLDINGS, LLC | B10: =IFERROR(__xludf.DUMMYFUNCTION("""COMPUTED_VALUE"""),4851.0) -> 4851 | C10: =IFERROR(__xludf.DUMMYFUNCTION("""COMPUTED_VALUE"""),"PK FISH HOLDINGS") -> PK FISH HOLDINGS | D10: =IFERROR(__xludf.DUMMYFUNCTION("""COMPUTED_VALUE"""),0.018349069875728208) -> 0.01834907 | E10: =IFERROR(__xludf.DUMMYFUNCTION("""COMPUTED_VALUE"""),0.021917286322302696) -> 0.021917286 | F10: =IFERROR(__xludf.DUMMYFUNCTION("""COMPUTED_VALUE"""),0.013352679375327567) -> 0.013352679 | G10: =IFERROR(__xludf.DUMMYFUNCTION("""COMPUTED_VALUE"""),0.01836465639772984) -> 0.018364656 | H10: =G10 -> 0.018364656 | I10: =G10 -> 0.018364656 | J10: =G10 -> 0.018364656
A11: LAURA FISHERIES JOINT VENTURE | B11: =IFERROR(__xludf.DUMMYFUNCTION("""COMPUTED_VALUE"""),3665.0) -> 3665 | C11: =IFERROR(__xludf.DUMMYFUNCTION("""COMPUTED_VALUE"""),"EVIE GRACE") -> EVIE GRACE | D11: =IFERROR(__xludf.DUMMYFUNCTION("""COMPUTED_VALUE"""),0.04176786761364475) -> 0.041767868 | E11: =IFERROR(__xludf.DUMMYFUNCTION("""COMPUTED_VALUE"""),0.04670766726162351) -> 0.046707667 | F11: =IFERROR(__xludf.DUMMYFUNCTION("""COMPUTED_VALUE"""),0.03981633234206593) -> 0.039816332 | G11: =IFERROR(__xludf.DUMMYFUNCTION("""COMPUTED_VALUE"""),0.042691697181148465) -> 0.042691697 | H11: =G11 -> 0.042691697 | I11: =G11 -> 0.042691697 | J11: =G11 -> 0.042691697
A12: MiRoCo LLC | B12: =IFERROR(__xludf.DUMMYFUNCTION("""COMPUTED_VALUE"""),3496.0) -> 3496 | C12: =IFERROR(__xludf.DUMMYFUNCTION("""COMPUTED_VALUE"""),"MiRoCo") -> MiRoCo | D12: =IFERROR(__xludf.DUMMYFUNCTION("""COMPUTED_VALUE"""),0.016202912580615066) -> 0.016202913 | E12: =IFERROR(__xludf.DUMMYFUNCTION("""COMPUTED_VALUE"""),0.034475369918002895) -> 0.03447537 | F12: =IFERROR(__xludf.DUMMYFUNCTION("""COMPUTED_VALUE"""),0.03406132275876516) -> 0.034061323 | G12: =IFERROR(__xludf.DUMMYFUNCTION("""COMPUTED_VALUE"""),0.02417689320528312) -> 0.024176893 | H12: =G12 -> 0.024176893 | I12: =G12 -> 0.024176893 | J12: =G12 -> 0.024176893
A13: DAVID DAHL | B13: =IFERROR(__xludf.DUMMYFUNCTION("""COMPUTED_VALUE"""),2319.0) -> 2319 | C13: =IFERROR(__xludf.DUMMYFUNCTION("""COMPUTED_VALUE"""),"LAURA") -> LAURA | D13: =IFERROR(__xludf.DUMMYFUNCTION("""COMPUTED_VALUE"""),0.01618306266729302) -> 0.016183063 | E13: =IFERROR(__xludf.DUMMYFUNCTION("""COMPUTED_VALUE"""),0.0026471844422184107) -> 0.0026471844 | F13: =IFERROR(__xludf.DUMMYFUNCTION("""COMPUTED_VALUE"""),0.004751083840038805) -> 0.0047510838 | G13: =IFERROR(__xludf.DUMMYFUNCTION("""COMPUTED_VALUE"""),0.010602655098172804) -> 0.010602655 | H13: =G13 -> 0.010602655 | I13: =G13 -> 0.010602655 | J13: =G13 -> 0.010602655
A14: BERING NORTH, LLC | B14: =IFERROR(__xludf.DUMMYFUNCTION("""COMPUTED_VALUE"""),3600.0) -> 3600 | C14: =IFERROR(__xludf.DUMMYFUNCTION("""COMPUTED_VALUE"""),"HICKORY WIND") -> HICKORY WIND | D14: =IFERROR(__xludf.DUMMYFUNCTION("""COMPUTED_VALUE"""),0.013795589759258051) -> 0.01379559 | E14: =IFERROR(__xludf.DUMMYFUNCTION("""COMPUTED_VALUE"""),0.009792863789423758) -> 0.0097928638 | F14: =IFERROR(__xludf.DUMMYFUNCTION("""COMPUTED_VALUE"""),0.006973904653277672) -> 0.0069739047 | G14: =IFERROR(__xludf.DUMMYFUNCTION("""COMPUTED_VALUE"""),0.01152012002257678) -> 0.01152012 | H14: =G14 -> 0.01152012 | I14: =H14 -> 0.01152012 | J14: =I14 -> 0.01152012
A15: BERING NORTH, LLC | B15: =IFERROR(__xludf.DUMMYFUNCTION("""COMPUTED_VALUE"""),3896.0) -> 3896 | C15: =IFERROR(__xludf.DUMMYFUNCTION("""COMPUTED_VALUE"""),"AMERICAN EAGLE") -> AMERICAN EAGLE | D15: =IFERROR(__xludf.DUMMYFUNCTION("""COMPUTED_VALUE"""),0.032543957891383875) -> 0.032543958 | E15: =IFERROR(__xludf.DUMMYFUNCTION("""COMPUTED_VALUE"""),0.022553834178472787) -> 0.022553834 | F15: =IFERROR(__xludf.DUMMYFUNCTION("""COMPUTED_VALUE"""),0.02029666588167881) -> 0.020296666 | G15: =IFERROR(__xludf.DUMMYFUNCTION("""COMPUTED_VALUE"""),0.02773305588264028) -> 0.027733056 | H15: =G15 -> 0.027733056 | I15: =H15 -> 0.027733056 | J15: =I15 -> 0.027733056
A16: VANGUARD FISHERIES LLC | B16: =IFERROR(__xludf.DUMMYFUNCTION("""COMPUTED_VALUE"""),2565.0) -> 2565 | C16: =IFERROR(__xludf.DUMMYFUNCTION("""COMPUTED_VALUE"""),"VANGUARD") -> VANGUARD | D16: =IFERROR(__xludf.DUMMYFUNCTION("""COMPUTED_VALUE"""),0.039000329698560314) -> 0.03900033 | E16: =IFERROR(__xludf.DUMMYFUNCTION("""COMPUTED_VALUE"""),0.003971010860478525) -> 0.0039710109 | F16: =IFERROR(__xludf.DUMMYFUNCTION("""COMPUTED_VALUE"""),0.012261359799791661) -> 0.01226136 | G16: =IFERROR(__xludf.DUMMYFUNCTION("""COMPUTED_VALUE"""),0.025075951017574344) -> 0.025075951 | H16: =G16 -> 0.025075951 | I16: =H16 -> 0.025075951 | J16: =I16 -> 0.025075951
A17: Total LLPs | B17: =IFERROR(__xludf.DUMMYFUNCTION("""COMPUTED_VALUE"""),11.0) -> 11 | C17: =IFERROR(__xludf.DUMMYFUNCTION("""COMPUTED_VALUE"""),"TOTAL") -> TOTAL | D17: =IFERROR(__xludf.DUMMYFUNCTION("""COMPUTED_VALUE"""),0.26485049348617845) -> 0.26485049 | E17: =IFERROR(__xludf.DUMMYFUNCTION("""COMPUTED_VALUE"""),0.23449840050551995) -> 0.2344984 | F17: =IFERROR(__xludf.DUMMYFUNCTION("""COMPUTED_VALUE"""),0.2196787920006778) -> 0.21967879 | G17: =IFERROR(__xludf.DUMMYFUNCTION("""COMPUTED_VALUE"""),0.24878723566923097) -> 0.24878724 | H17: =G17 -> 0.24878724 | I17: =H17 -> 0.24878724 | J17: =I17 -> 0.24878724
A20: North Pacific
A21: MEMBER INFORMATION | D21: HARVEST ALLOCATIONS (% of CV POOL)
A22: Member | B22: LLP No. | C22: Vessel | D22: POP | E22: Northern | F22: Dusky | G22: Sablefish | H22: Pacific Cod | I22: Thornyhead | J22: Halibut PSC
A23: NICOLE FISHERIES LLC | B23: =IFERROR(__xludf.DUMMYFUNCTION("IMPORTRANGE(""https://docs.google.com/spreadsheets/d/1fpr4iXJjYPIWfqLVGaDLSDFHokxxaVbtvYkSxFtDSHM/edit#gid=1391174979"", ""'CV Coop LLP Primary Alloc'!A29:B40"")"),2487.0) -> 2487 | C23: =IFERROR(__xludf.DUMMYFUNCTION("""COMPUTED_VALUE"""),"NICHOLE") -> NICHOLE | D23: =IFERROR(__xludf.DUMMYFUNCTION("IMPORTRANGE(""https://docs.google.com/spreadsheets/d/1fpr4iXJjYPIWfqLVGaDLSDFHokxxaVbtvYkSxFtDSHM/edit#gid=1391174979"", ""'CV Coop LLP Primary Alloc'!P29:R40"")"),0.02243063538622548) -> 0.022430635 | E23: =IFERROR(__xludf.DUMMYFUNCTION("""COMPUTED_VALUE"""),0.028709364001966678) -> 0.028709364 | F23: =IFERROR(__xludf.DUMMYFUNCTION("""COMPUTED_VALUE"""),0.04209939998976728) -> 0.0420994 | G23: =IFERROR(__xludf.DUMMYFUNCTION("IMPORTRANGE(""https://docs.google.com/spreadsheets/d/1fpr4iXJjYPIWfqLVGaDLSDFHokxxaVbtvYkSxFtDSHM/edit#gid=1392452204"", ""'CV Secondary & PSC Alloc'!G40:G51"")"),0.02762955084492421) -> 0.027629551 | H23: =G23 -> 0.027629551 | I23: =H23 -> 0.027629551 | J23: =I23 -> 0.027629551
A24: MAGIC FISH CO. | B24: =IFERROR(__xludf.DUMMYFUNCTION("""COMPUTED_VALUE"""),1541.0) -> 1541 | C24: =IFERROR(__xludf.DUMMYFUNCTION("""COMPUTED_VALUE"""),"SEA MAC - MAGIC") -> SEA MAC - MAGIC | D24: =IFERROR(__xludf.DUMMYFUNCTION("""COMPUTED_VALUE"""),0.01852386911243821) -> 0.018523869 | E24: =IFERROR(__xludf.DUMMYFUNCTION("""COMPUTED_VALUE"""),0.0034961310990973176) -> 0.0034961311 | F24: =IFERROR(__xludf.DUMMYFUNCTION("""COMPUTED_VALUE"""),0.00406158088617346) -> 0.0040615809 | G24: =IFERROR(__xludf.DUMMYFUNCTION("""COMPUTED_VALUE"""),0.012006733571514898) -> 0.012006734 | H24: =G24 -> 0.012006734 | I24: =H24 -> 0.012006734 | J24: =I24 -> 0.012006734
A25: SEA MAC SEAFOODS, LLC | B25: =IFERROR(__xludf.DUMMYFUNCTION("""COMPUTED_VALUE"""),3785.0) -> 3785 | C25: =IFERROR(__xludf.DUMMYFUNCTION("""COMPUTED_VALUE"""),"SEA MAC ") -> SEA MAC | D25: =IFERROR(__xludf.DUMMYFUNCTION("""COMPUTED_VALUE"""),0.008504696196159943) -> 0.0085046962 | E25: =IFERROR(__xludf.DUMMYFUNCTION("""COMPUTED_VALUE"""),0.008607790175494375) -> 0.0086077902 | F25: =IFERROR(__xludf.DUMMYFUNCTION("""COMPUTED_VALUE"""),0.008272957777283875) -> 0.0082729578 | G25: =IFERROR(__xludf.DUMMYFUNCTION("""COMPUTED_VALUE"""),0.008489268723574103) -> 0.0084892687 | H25: =G25 -> 0.0084892687 | I25: =H25 -> 0.0084892687 | J25: =I25 -> 0.0084892687
